2024-06-04 19:54:20.046 | ERROR    | __main__:<module>:35 - Error while starting bot [app - runner.py]
Traceback (most recent call last):

> File "F:\Projects\TelegramTrader\app\runner.py", line 33, in <module>
    telegram = Telegram(telegramSettings.api_id, telegramSettings.api_hash)
               │        │                        └ <Configuration: 0x248ff31ba30>
               │        └ <Configuration: 0x248ff31ba30>
               └ <module 'Telegram' from 'F:\\Projects\\TelegramTrader\\app\\Telegram\\__init__.py'>

TypeError: 'module' object is not callable
2024-06-04 19:54:22.429 | ERROR    | __main__:<module>:35 - Error while starting bot [app - runner.py]
Traceback (most recent call last):

> File "F:\Projects\TelegramTrader\app\runner.py", line 33, in <module>
    telegram = Telegram(telegramSettings.api_id, telegramSettings.api_hash)
               │        │                        └ <Configuration: 0x241d37cba30>
               │        └ <Configuration: 0x241d37cba30>
               └ <module 'Telegram' from 'F:\\Projects\\TelegramTrader\\app\\Telegram\\__init__.py'>

TypeError: 'module' object is not callable
2024-06-04 19:54:54.955 | ERROR    | __main__:<module>:35 - Error while starting bot [app - runner.py]
Traceback (most recent call last):

> File "F:\Projects\TelegramTrader\app\runner.py", line 33, in <module>
    telegram = Telegram(telegramSettings.api_id, telegramSettings.api_hash)
               │        │                        └ <Configuration: 0x2d846bfba30>
               │        └ <Configuration: 0x2d846bfba30>
               └ <module 'Telegram' from 'F:\\Projects\\TelegramTrader\\app\\Telegram\\__init__.py'>

TypeError: 'module' object is not callable
2024-06-04 20:10:45.112 | ERROR    | __main__:<module>:50 - Error while starting bot [app - runner.py]
Traceback (most recent call last):

> File "F:\Projects\TelegramTrader\app\runner.py", line 41, in <module>
    ConfigLogger()
    └ <function ConfigLogger at 0x0000023DAF407E20>

  File "F:\Projects\TelegramTrader\app\runner.py", line 33, in ConfigLogger
    telegram.notify(message='Bot Started!', **params)#, chat_id=1234
    │        │                                └ {'token': '7328441575:AAFt4YnH7Ztd_pO3BfrQlqpWtCl82EQ1Oyk'}
    │        └ <function Provider.notify at 0x0000023DAF3D8B80>
    └ <Provider:[Telegram]>

  File "C:\Python310\lib\site-packages\notifiers\core.py", line 303, in notify
    data = self._process_data(**kwargs)
           │    │               └ {'message': 'Bot Started!', 'token': '7328441575:AAFt4YnH7Ztd_pO3BfrQlqpWtCl82EQ1Oyk'}
           │    └ <function SchemaResource._process_data at 0x0000023DAF3D8670>
           └ <Provider:[Telegram]>

  File "C:\Python310\lib\site-packages\notifiers\core.py", line 235, in _process_data
    self._validate_data(data)
    │    │              └ {'message': 'Bot Started!', 'token': '7328441575:AAFt4YnH7Ztd_pO3BfrQlqpWtCl82EQ1Oyk'}
    │    └ <function SchemaResource._validate_data at 0x0000023DAF3D8550>
    └ <Provider:[Telegram]>

  File "C:\Python310\lib\site-packages\notifiers\core.py", line 208, in _validate_data
    raise BadArguments(validation_error=msg, provider=self.name, data=data)
          │                             │             │    │          └ {'message': 'Bot Started!', 'token': '7328441575:AAFt4YnH7Ztd_pO3BfrQlqpWtCl82EQ1Oyk'}
          │                             │             │    └ 'telegram'
          │                             │             └ <Provider:[Telegram]>
          │                             └ "'chat_id' is a required property"
          └ <class 'notifiers.exceptions.BadArguments'>

notifiers.exceptions.BadArguments: Error with sent data: 'chat_id' is a required property
2024-06-04 20:15:32.587 | ERROR    | __main__:<module>:51 - Error while starting bot [app - runner.py]
Traceback (most recent call last):

> File "F:\Projects\TelegramTrader\app\runner.py", line 49, in <module>
    telegram = Telegram(telegramSettings.api_id, telegramSettings.api_hash)
               │        │                        └ <Configuration: 0x1992bfa6a40>
               │        └ <Configuration: 0x1992bfa6a40>
               └ <module 'Telegram' from 'F:\\Projects\\TelegramTrader\\app\\Telegram\\__init__.py'>

TypeError: 'module' object is not callable
2024-06-04 20:16:30.707 | ERROR    | __main__:<module>:51 - Error while starting bot [app - runner.py]
Traceback (most recent call last):

> File "F:\Projects\TelegramTrader\app\runner.py", line 49, in <module>
    telegram = Telegram(telegramSettings.api_id, telegramSettings.api_hash)
               │        │                        └ <Configuration: 0x27493b36a40>
               │        └ <Configuration: 0x27493b36a40>
               └ <module 'Telegram' from 'F:\\Projects\\TelegramTrader\\app\\Telegram\\__init__.py'>

TypeError: 'module' object is not callable
2024-06-04 20:17:59.313 | ERROR    | __main__:<module>:52 - Error while starting bot [app - runner.py]
Traceback (most recent call last):

> File "F:\Projects\TelegramTrader\app\runner.py", line 43, in <module>
    ConfigLogger()
    └ <function ConfigLogger at 0x000001EF66D2FF40>

  File "F:\Projects\TelegramTrader\app\runner.py", line 27, in ConfigLogger
    logger.add(sys.stderr, format="{time} {level} {message}", filter="my_module", level="INFO")
    │      └ <function Logger.add at 0x000001EF652A7A30>
    └ <loguru.logger handlers=[(id=0, level=10, sink=<stderr>), (id=1, level=10, sink='../Logs/{time:YYYY-MM-DD}.log')]>

NameError: name 'sys' is not defined
2024-06-04 20:18:07.783 | ERROR    | __main__:<module>:52 - Error while starting bot [app - runner.py]
Traceback (most recent call last):

> File "F:\Projects\TelegramTrader\app\runner.py", line 50, in <module>
    telegram = Telegram(telegramSettings.api_id, telegramSettings.api_hash)
               │        │                        └ <Configuration: 0x24781f26e60>
               │        └ <Configuration: 0x24781f26e60>
               └ <module 'Telegram' from 'F:\\Projects\\TelegramTrader\\app\\Telegram\\__init__.py'>

TypeError: 'module' object is not callable
2024-06-04 20:18:27.173 | ERROR    | __main__:<module>:52 - Error while starting bot [app - runner.py]
Traceback (most recent call last):

> File "F:\Projects\TelegramTrader\app\runner.py", line 50, in <module>
    telegram = Telegram(telegramSettings.api_id, telegramSettings.api_hash)
               │        │                        └ <Configuration: 0x27274286d70>
               │        └ <Configuration: 0x27274286d70>
               └ <module 'Telegram' from 'F:\\Projects\\TelegramTrader\\app\\Telegram\\__init__.py'>

TypeError: 'module' object is not callable
2024-06-04 20:19:15.468 | ERROR    | __main__:<module>:50 - Error while starting bot [app - runner.py]
Traceback (most recent call last):

> File "F:\Projects\TelegramTrader\app\runner.py", line 48, in <module>
    telegram = Telegram(telegramSettings.api_id, telegramSettings.api_hash)
               │        │                        └ <Configuration: 0x1d049256a10>
               │        └ <Configuration: 0x1d049256a10>
               └ <module 'Telegram' from 'F:\\Projects\\TelegramTrader\\app\\Telegram\\__init__.py'>

TypeError: 'module' object is not callable
2024-06-04 20:27:16.563 | ERROR    | __main__:<module>:58 - Error while starting bot [app - runner.py]
Traceback (most recent call last):

> File "F:\Projects\TelegramTrader\app\runner.py", line 52, in <module>
    ConfigNotification(cfg.Notification.token, cfg.Notification.chatId)
    │                  │                       └ <JSONConfiguration: 0x293445e00a0>
    │                  └ <JSONConfiguration: 0x293445e00a0>
    └ <function ConfigNotification at 0x0000029345C23F40>

  File "C:\Python310\lib\site-packages\config\configuration.py", line 176, in __getattr__
    raise AttributeError(item) from None
                         └ 'chatId'

AttributeError: chatId
